Workbook
Name DC: 'Depreciation Calculator'!$A$2:$D$45
Name Depreciation_Calculator: 'Depreciation Calculator'!$D$11

Sheet Information

Sheet Depreciation Calculator
C2: Coachx.live
C3: Depreciation Calculator
B5: Straight Line Method
B6: Asset Cost | D6: 450000
B7: Additonal Asset Cost | D7: 50000
B8: Asset Price | D8: =SUM(D6:D7) -> 500000
B9: Scrap Value | D9: 50000
B10: Estimated Life Span (Years) | D10: 10
B11: Depreciation / Year as per Straight Line Method | D11: =IF(D8="", "", SLN($D$8,$D$9,$D$10)) -> 45000
B12: Depreciation Percentage | D12: =IFERROR(D11/D8,"") -> 0.09
B13: Total Depreciation For Its Life Span | D13: =IF(D8="", "", D11*D10) -> 450000
B14: Depreciated Book Value After Its Life Span | D14: =IF(D8="", "", D8-D13) -> 50000
B15: Balance Amount | D15: =IF(D8="", "", D8-D13-D9) -> 0
B17: Diminishing Balance Method
B18: Asset Cost | D18: 450000
B19: Additonal Asset Cost | D19: 50000
B20: Asset Price | D20: =D8 -> 500000
B21: Scrap Value | D21: 50000
B22: Estimated Life Span (Years) | D22: 10
B23: Rate of Depreciation as per Diminishing Balance Method | D23: =IF(D20="","",1-(D21/D20)^(1/D22)) -> 0.20567177
B24: Depreciation Schedule
B25: Year | C25: Year on Year Depreciation Amount | D25: Book Value
B26: 1 | C26: =D26* $D$23 -> 102835.88 | D26: =D20 -> 500000
B27: 2 | C27: =IFERROR(IF(D27>$D$21, (D27*$D$23), ""),"") -> 81685.445 | D27: =IFERROR(D26-C26, "") -> 397164.12
B28: 3 | C28: =IFERROR(IF(D28>$D$21, (D28*$D$23), ""),"") -> 64885.055 | D28: =IFERROR(D27-C27, "") -> 315478.67
B29: 4 | C29: =IFERROR(IF(D29>$D$21, (D29*$D$23), ""),"") -> 51540.032 | D29: =IFERROR(D28-C28, "") -> 250593.62
B30: 5 | C30: =IFERROR(IF(D30>$D$21, (D30*$D$23), ""),"") -> 40939.702 | D30: =IFERROR(D29-C29, "") -> 199053.59
B31: 6 | C31: =IFERROR(IF(D31>$D$21, (D31*$D$23), ""),"") -> 32519.561 | D31: =IFERROR(D30-C30, "") -> 158113.88
B32: 7 | C32: =IFERROR(IF(D32>$D$21, (D32*$D$23), ""),"") -> 25831.206 | D32: =IFERROR(D31-C31, "") -> 125594.32
B33: 8 | C33: =IFERROR(IF(D33>$D$21, (D33*$D$23), ""),"") -> 20518.456 | D33: =IFERROR(D32-C32, "") -> 99763.116
B34: 9 | C34: =IFERROR(IF(D34>$D$21, (D34*$D$23), ""),"") -> 16298.389 | D34: =IFERROR(D33-C33, "") -> 79244.66
B35: 10 | C35: =IFERROR(IF(D35>$D$21, (D35*$D$23), ""),"") -> 12946.271 | D35: =IFERROR(D34-C34, "") -> 62946.271
B36: 11 | C36: =IFERROR(IF(D36>$D$21, (D36*$D$23), ""),"") | D36: =IFERROR(D35-C35, "") -> 50000
C37: =IFERROR(IF(D37>$D$21, (D37*$D$23), ""),"") | D37: =IFERROR(D36-C36, "")
C38: =IFERROR(IF(D38>$D$21, (D38*$D$23), ""),"") | D38: =IFERROR(D37-C37, "")
C39: =IFERROR(IF(D39>$D$21, (D39*$D$23), ""),"") | D39: =IFERROR(D38-C38, "")
C40: =IFERROR(IF(D40>$D$21, (D40*$D$23), ""),"") | D40: =IFERROR(D39-C39, "")
C41: =IFERROR(IF(D41>$D$21, (D41*$D$23), ""),"") | D41: =IFERROR(D40-C40, "")
C42: =IFERROR(IF(D42>$D$21, (D42*$D$23), ""),"") | D42: =IFERROR(D41-C41, "")
C43: =IFERROR(IF(D43>$D$21, (D43*$D$23), ""),"") | D43: =IFERROR(D42-C42, "")
...

Sheet Extra
A1: ADVANCE QUESTIONS
A2: Annual Depreciation | B2: ='Depreciation Calculator'!D11 -> 45000
A3: Total Depreciation | B3: ='Depreciation Calculator'!D13 -> 450000
A4: Book Value After Life | B4: ='Depreciation Calculator'!D14 -> 50000
A5: Rate | B5: ='Depreciation Calculator'!D23 -> 0.20567177
A6: Book Value in 4th Year | B6: ='Depreciation Calculator'!D28 -> 315478.67
A7: Total Depreciation | B7: ='Depreciation Calculator'!D20 - 'Depreciation Calculator'!D21 -> 450000
A8: Book Value After Life | B8: ='Depreciation Calculator'!D21 -> 50000
A11: DATA TABLE
A12: Year | B12: SLM Book Value | C12: DBM Book Value
A13: 1 | B13: 455000 | C13: 397164.12
A14: 2 | B14: 410000 | C14: 315478.67
A15: 3 | B15: 365000 | C15: 250593.62
A16: 4 | B16: 320000 | C16: 199053.59
A17: 5 | B17: 275000 | C17: 158113.88
A18: 6 | B18: 230000 | C18: 125594.32
A19: 7 | B19: 185000 | C19: 99763.12
A20: 8 | B20: 140000 | C20: 79244.66
A21: 9 | B21: 95,0
A24: Depreciation Comparison
A25: Year | B25: SLM Depreciation | C25: DBM Depreciation
A26: 1 | B26: 45000 | C26: 102835.88
A27: 2 | B27: 45000 | C27: 81685.45
A28: 3 | B28: 45000 | C28: 64885.06
A29: 4 | B29: 45000 | C29: 51540.03
A30: 5 | B30: 45000 | C30: 40939.7
A31: 6 | B31: 45000 | C31: 32519.56
A32: 7 | B32: 45000 | C32: 25831.21
A33: 8 | B33: 45000 | C33: 20518.46
A34: 9 | B34: 45000 | C34: 16298.39
A35: 10 | B35: 45000 | C35: 12946.27
